<?xml version="1.0" ?>
<!-- =================================================================================== -->
<!-- |    This document was autogenerated by xacro from /home/duygiang/doosan_ws/src/doosan-robot/dsr_description/xacro/base_m0609.urdf.xacro | -->
<!-- |    EDITING THIS FILE BY HAND IS NOT RECOMMENDED                                 | -->
<!-- =================================================================================== -->
<robot name="m0609">
    <joint name="camera_joint" type="fixed">
        <parent link="base_0" />
        <child link="kinect_link" />
        <origin rpy="0 1.57 1.57" xyz="-0.1 -0.65 1.08" />
    </joint>
    <link name="kinect_link">
        <visual>
            <origin rpy="0 0 0" xyz=" 0 0 0" />
            <geometry>
                <!-- <mesh filename="package://dsr_description/meshes/sensors/kinect.dae"/> -->
                <box size="0.005 0.005 0.005" />
            </geometry>
            <material name="kinect_gray">
                <color rgba="0.2 0.2 0.2 1.0" />
            </material>
        </visual>
        <collision>
            <origin rpy="0.0 0.0 0.0" xyz="0.0 0.0 0.0" />
            <origin rpy="0 0 " xyz="0 0 0" />
            <geometry>
                <!-- <box size="0.05 0.2 0.05" /> -->
                <box size="0.0 0.0 0.0" />
            </geometry>
        </collision>
        <inertial>
            <origin rpy="0.0 0.0 0.0" xyz="0.0 0.0 0.0" />
            <mass value="0.1" />
            <inertia ixx="0.001" ixy="0.0" ixz="0.0" iyy="0.001" iyz="0.0" izz="0.001" />
        </inertial>
    </link>
    <joint name="camera_optical_joint" type="fixed">
        <origin rpy="-1.5707963267948966 0 -1.5707963267948966" xyz="0.0 0.0 0.0" />
        <parent link="kinect_link" />
        <child link="camera_link_optical" />
    </joint>
    <link name="camera_link_optical" />
    <!-- camera -->
    <gazebo reference="kinect_link">
        <sensor name="camera" type="depth">
            <always_on>1</always_on>
            <visualize>true</visualize>
            <update_rate>10</update_rate>
            <camera>
                <horizontal_fov>1.047</horizontal_fov>
                <image>
                    <format>R8G8B8</format>
                    <width>640</width>
                    <height>480</height>
                </image>
                <clip>
                    <near>0.1</near>
                    <far>100</far>
                </clip>
            </camera>
            <plugin filename="libgazebo_ros_openni_kinect.so" name="camera_controller">
                <alwaysOn>true</alwaysOn>
                <updateRate>10</updateRate>
                <imageTopicName>kinect</imageTopicName>
                <cameraInfoTopicName>camera/camera_info</cameraInfoTopicName>
                <depthImageTopicName>camera/depth/image_raw</depthImageTopicName>
                <depthImageCameraInfoTopicName>camera/depth/camera_info</depthImageCameraInfoTopicName>
                <pointCloudTopicName>camera/depth/points</pointCloudTopicName>
                <frameName>camera_link_optical</frameName>
                <pointCloudCutoff>0.4</pointCloudCutoff>
                <hackBaseline>0.07</hackBaseline>
                <distortion_k1>0.0</distortion_k1>
                <distortion_k2>0.0</distortion_k2>
                <distortion_k3>0.0</distortion_k3>
                <distortion_t1>0.0</distortion_t1>
                <distortion_t2>0.0</distortion_t2>
                <CxPrime>0.0</CxPrime>
                <Cx>0.0</Cx>
                <Cy>0.0</Cy>
                <focallength>0.0</focallength>
            </plugin>
        </sensor>
        <plugin name="gazebo_ros_control">
            <robotNamespace>/</robotNamespace>
        </plugin>
    </gazebo>
    <material name="black">
        <color rgba="0.0 0.0 0.0 1.0" />
    </material>
    <material name="white">
        <color rgba="1.0 1.0 1.0 1.0" />
    </material>
    <material name="orange">
        <color rgba="1.0 0.4 0.0 1.0" />
    </material>
    <material name="dr_gray">
        <color rgba="0.490 0.490 0.486 1.0" />
    </material>
    <material name="dr_white">
        <color rgba="0.941 0.941 0.941 1.0" />
    </material>
    <link name="base_0">
        <inertial>
            <mass value="3.18" />
            <origin xyz="-2.8e-05   -0.006045    0.038403" rpy="0 0 0" />
            <inertia ixx="0.017789" ixy="-7.4356e-06" ixz="3.0378e-06" iyy="0.011135" iyz="-0.00029038" izz="0.020054" />
        </inertial>
        <collision>
            <origin rpy="0 0 0" xyz="0 0 0" />
            <geometry>
                <mesh filename="package://dsr_description/meshes/m0609_collision/MF0609_0_0.dae" scale="0.001 0.001 0.001" />
            </geometry>
        </collision>
        <visual>
            <origin rpy="0 0 0" xyz="0 0 0" />
            <geometry>
                <mesh filename="package://dsr_description/meshes/m0609_white/MF0609_0_0.dae" scale="0.001 0.001 0.001" />
            </geometry>
        </visual>
    </link>
    <!-- joint 1 -->
    <joint name="joint1" type="revolute">
        <parent link="base_0" />
        <child link="link1" />
        <origin rpy="0 0 0" xyz="0 0 0.1" />
        <axis xyz="0 0 1" />
        <limit effort="163" lower="-6.2832" upper="6.2832" velocity="2.618" />
        <dynamics friction="0" />
    </joint>
    <link name="link1">
        <inertial>
            <mass value="5.02" />
            <origin xyz="7.2e-05    0.036227   -0.003417" rpy="0 0 0" />
            <inertia ixx="0.026195" ixy="2.3904e-05" ixz="-1.3319e-05" iyy="0.016899" iyz="-0.00071987" izz="0.022944" />
        </inertial>
        <collision>
            <origin rpy="0 0 0" xyz="0 0 0" />
            <geometry>
                <mesh filename="package://dsr_description/meshes/m0609_collision/MF0609_1_0.dae" scale="0.001 0.001 0.001" />
            </geometry>
        </collision>
        <visual>
            <origin rpy="0 0 0" xyz="0 0 0" />
            <geometry>
                <mesh filename="package://dsr_description/meshes/m0609_white/MF0609_1_0.dae" scale="0.001 0.001 0.001" />
            </geometry>
        </visual>
    </link>
    <!-- joint2 -->
    <joint name="joint2" type="revolute">
        <parent link="link1" />
        <child link="link2" />
        <origin rpy="0 -1.571 -1.571" xyz="0 0.0062 0" />
        <axis xyz="0 0 1" />
        <limit effort="163" lower="-6.2832" upper="6.2832" velocity="2.618" />
        <dynamics friction="0" />
    </joint>
    <link name="link2">
        <inertial>
            <mass value="8.04" />
            <origin xyz="0.20447     2.6e-05     0.16005" rpy="0 0 0" />
            <inertia ixx="0.026743" ixy="-0.00019461" ixz="-0.00058734" iyy="0.30084" iyz="-6.7892e-06" izz="0.29898" />
        </inertial>
        <collision>
            <origin rpy="0 0 0" xyz="0 0 0" />
            <geometry>
                <mesh filename="package://dsr_description/meshes/m0609_collision/MF0609_2_0.dae" scale="0.001 0.001 0.001" />
            </geometry>
        </collision>
        <visual>
            <origin rpy="0 0 0" xyz="0 0 0" />
            <geometry>
                <mesh filename="package://dsr_description/meshes/m0609_white/MF0609_2_0.dae" scale="0.001 0.001 0.001" />
            </geometry>
        </visual>
        <collision>
            <origin rpy="0 0 0" xyz="0 0 0" />
            <geometry>
                <mesh filename="package://dsr_description/meshes/m0609_collision/MF0609_2_1.dae" scale="0.001 0.001 0.001" />
            </geometry>
        </collision>
        <visual>
            <origin rpy="0 0 0" xyz="0 0 0" />
            <geometry>
                <mesh filename="package://dsr_description/meshes/m0609_white/MF0609_2_1.dae" scale="0.001 0.001 0.001" />
            </geometry>
        </visual>
        <collision>
            <origin rpy="0 0 0" xyz="0 0 0" />
            <geometry>
                <mesh filename="package://dsr_description/meshes/m0609_collision/MF0609_2_2.dae" scale="0.001 0.001 0.001" />
            </geometry>
        </collision>
        <visual>
            <origin rpy="0 0 0" xyz="0 0 0" />
            <geometry>
                <mesh filename="package://dsr_description/meshes/m0609_white/MF0609_2_2.dae" scale="0.001 0.001 0.001" />
            </geometry>
        </visual>
    </link>
    <!-- joint3 -->
    <joint name="joint3" type="revolute">
        <parent link="link2" />
        <child link="link3" />
        <origin rpy="0 0 1.571" xyz="0.411 0 0" />
        <axis xyz="0 0 1" />
        <limit effort="96" lower="-2.618" upper="2.618" velocity="3.1416" />
        <dynamics friction="0" />
    </joint>
    <link name="link3">
        <inertial>
            <mass value="3.6" />
            <origin xyz="-2.2e-05   -0.006867    0.043445" rpy="0 0 0" />
            <inertia ixx="0.018342" ixy="1.1302e-05" ixz="-4.5308e-06" iyy="0.018239" iyz="-0.00099247" izz="0.01326" />
        </inertial>
        <collision>
            <origin rpy="0 0 0" xyz="0 0 0" />
            <geometry>
                <mesh filename="package://dsr_description/meshes/m0609_collision/MF0609_3_0.dae" scale="0.001 0.001 0.001" />
            </geometry>
        </collision>
        <visual>
            <origin rpy="0 0 0" xyz="0 0 0" />
            <geometry>
                <mesh filename="package://dsr_description/meshes/m0609_white/MF0609_3_0.dae" scale="0.001 0.001 0.001" />
            </geometry>
        </visual>
    </link>
    <!-- joint4 -->
    <joint name="joint4" type="revolute">
        <parent link="link3" />
        <child link="link4" />
        <origin rpy="1.571 0 0" xyz="0 -0.368 0" />
        <axis xyz="0 0 1" />
        <limit effort="50" lower="-6.2832" upper="6.2832" velocity="3.927" />
        <dynamics friction="0" />
    </joint>
    <link name="link4">
        <inertial>
            <mass value="3.57" />
            <origin xyz="4e-05    0.097079    -0.10981" rpy="0 0 0" />
            <inertia ixx="0.08035" ixy="-4.6119e-06" ixz="-8.1798e-06" iyy="0.066005" iyz="-0.028996" izz="0.029763" />
        </inertial>
        <collision>
            <origin rpy="0 0 0" xyz="0 0 0" />
            <geometry>
                <mesh filename="package://dsr_description/meshes/m0609_collision/MF0609_4_0.dae" scale="0.001 0.001 0.001" />
            </geometry>
        </collision>
        <visual>
            <origin rpy="0 0 0" xyz="0 0 0" />
            <geometry>
                <mesh filename="package://dsr_description/meshes/m0609_white/MF0609_4_0.dae" scale="0.001 0.001 0.001" />
            </geometry>
        </visual>
        <collision>
            <origin rpy="0 0 0" xyz="0 0 0" />
            <geometry>
                <mesh filename="package://dsr_description/meshes/m0609_collision/MF0609_4_1.dae" scale="0.001 0.001 0.001" />
            </geometry>
        </collision>
        <visual>
            <origin rpy="0 0 0" xyz="0 0 0" />
            <geometry>
                <mesh filename="package://dsr_description/meshes/m0609_white/MF0609_4_1.dae" scale="0.001 0.001 0.001" />
            </geometry>
        </visual>
    </link>
    <!-- joint5 -->
    <joint name="joint5" type="revolute">
        <parent link="link4" />
        <child link="link5" />
        <origin rpy="-1.571 0 0" xyz="0 0 0" />
        <axis xyz="0 0 1" />
        <limit effort="50" lower="-6.2832" upper="6.2832" velocity="3.927" />
        <dynamics friction="0" />
    </joint>
    <link name="link5">
        <inertial>
            <mass value="2.83" />
            <origin xyz="-6.8e-05    0.003827    0.031969" rpy="0 0 0" />
            <inertia ixx="0.014275" ixy="2.2026e-05" ixz="3.3017e-06" iyy="0.012569" iyz="0.00045077" izz="0.0085318" />
        </inertial>
        <collision>
            <origin rpy="0 0 0" xyz="0 0 0" />
            <geometry>
                <mesh filename="package://dsr_description/meshes/m0609_collision/MF0609_5_0.dae" scale="0.001 0.001 0.001" />
            </geometry>
        </collision>
        <visual>
            <origin rpy="0 0 0" xyz="0 0 0" />
            <geometry>
                <mesh filename="package://dsr_description/meshes/m0609_white/MF0609_5_0.dae" scale="0.001 0.001 0.001" />
            </geometry>
        </visual>
    </link>
    <!-- joint6 -->
    <joint name="joint6" type="revolute">
        <parent link="link5" />
        <child link="link6" />
        <origin rpy="1.571 0 0" xyz="0 -0.121 0" />
        <axis xyz="0 0 1" />
        <limit effort="50" lower="-6.2832" upper="6.2832" velocity="3.927" />
        <dynamics friction="0" />
    </joint>
    <link name="link6">
        <inertial>
            <mass value="1.16" />
            <origin xyz="-3e-05    -4.5e-05     -0.0539" rpy="0 0 0" />
            <inertia ixx="0.0080226" ixy="1.371e-06" ixz="6.3578e-06" iyy="0.0053992" iyz="7.4676e-06" izz="0.0053912" />
        </inertial>
        <collision>
            <origin rpy="0 0 0" xyz="0 0 0" />
            <geometry>
                <mesh filename="package://dsr_description/meshes/m0609_collision/MF0609_6_0.dae" scale="0.001 0.001 0.001" />
            </geometry>
        </collision>
        <visual>
            <origin rpy="0 0 0" xyz="0 0 0" />
            <geometry>
                <mesh filename="package://dsr_description/meshes/m0609_white/MF0609_6_0.dae" scale="0.001 0.001 0.001" />
            </geometry>
        </visual>
    </link>
    <!-- Transmission 1 -->
    <transmission name="tran1">
        <type>transmission_interface/SimpleTransmission</type>
        <joint name="joint1">
            <hardwareInterface>hardware_interface/PositionJointInterface</hardwareInterface>
        </joint>
        <actuator name="motor1">
            <hardwareInterface>hardware_interface/PositionJointInterface</hardwareInterface>
            <mechanicalReduction>1</mechanicalReduction>
        </actuator>
    </transmission>
    <!-- Transmission 2 -->
    <transmission name="tran2">
        <type>transmission_interface/SimpleTransmission</type>
        <joint name="joint2">
            <hardwareInterface>hardware_interface/PositionJointInterface</hardwareInterface>
        </joint>
        <actuator name="motor2">
            <hardwareInterface>hardware_interface/PositionJointInterface</hardwareInterface>
            <mechanicalReduction>1</mechanicalReduction>
        </actuator>
    </transmission>
    <!-- Transmission 3 -->
    <transmission name="tran3">
        <type>transmission_interface/SimpleTransmission</type>
        <joint name="joint3">
            <hardwareInterface>hardware_interface/PositionJointInterface</hardwareInterface>
        </joint>
        <actuator name="motor3">
            <hardwareInterface>hardware_interface/PositionJointInterface</hardwareInterface>
            <mechanicalReduction>1</mechanicalReduction>
        </actuator>
    </transmission>
    <!-- Transmission 4 -->
    <transmission name="tran4">
        <type>transmission_interface/SimpleTransmission</type>
        <joint name="joint4">
            <hardwareInterface>hardware_interface/PositionJointInterface</hardwareInterface>
        </joint>
        <actuator name="motor4">
            <hardwareInterface>hardware_interface/PositionJointInterface</hardwareInterface>
            <mechanicalReduction>1</mechanicalReduction>
        </actuator>
    </transmission>
    <!-- Transmission 5 -->
    <transmission name="tran5">
        <type>transmission_interface/SimpleTransmission</type>
        <joint name="joint5">
            <hardwareInterface>hardware_interface/PositionJointInterface</hardwareInterface>
        </joint>
        <actuator name="motor5">
            <hardwareInterface>hardware_interface/PositionJointInterface</hardwareInterface>
            <mechanicalReduction>1</mechanicalReduction>
        </actuator>
    </transmission>
    <!-- Transmission 6 -->
    <transmission name="tran6">
        <type>transmission_interface/SimpleTransmission</type>
        <joint name="joint6">
            <hardwareInterface>hardware_interface/PositionJointInterface</hardwareInterface>
        </joint>
        <actuator name="motor6">
            <hardwareInterface>hardware_interface/PositionJointInterface</hardwareInterface>
            <mechanicalReduction>1</mechanicalReduction>
        </actuator>
    </transmission>
    <!-- Base -->
    <selfCollide>true</selfCollide>
    <gazebo reference="dsr01">
        <selfCollide>true</selfCollide>
    </gazebo>
    <gazebo reference="base_0">
        <selfCollide>true</selfCollide>
        <kp>1000000.0</kp>
        <kd>100.0</kd>
        <mu1>30.0</mu1>
        <mu2>30.0</mu2>
        <maxVel>1.0</maxVel>
        <minDepth>0.001</minDepth>
    </gazebo>
    <!-- Link1 -->
    <gazebo reference="link1">
        <selfCollide>true</selfCollide>
        <kp>1000000.0</kp>
        <kd>100.0</kd>
        <mu1>30.0</mu1>
        <mu2>30.0</mu2>
        <maxVel>1.0</maxVel>
        <minDepth>0.001</minDepth>
    </gazebo>
    <!-- Link2 -->
    <gazebo reference="link2">
        <selfCollide>true</selfCollide>
        <kp>1000000.0</kp>
        <kd>100.0</kd>
        <mu1>30.0</mu1>
        <mu2>30.0</mu2>
        <maxVel>1.0</maxVel>
        <minDepth>0.001</minDepth>
    </gazebo>
    <!-- Link3 -->
    <gazebo reference="link3">
        <selfCollide>true</selfCollide>
        <kp>1000000.0</kp>
        <kd>100.0</kd>
        <mu1>30.0</mu1>
        <mu2>30.0</mu2>
        <maxVel>1.0</maxVel>
        <minDepth>0.001</minDepth>
    </gazebo>
    <!-- Link4 -->
    <gazebo reference="link4">
        <selfCollide>true</selfCollide>
        <kp>1000000.0</kp>
        <kd>100.0</kd>
        <mu1>30.0</mu1>
        <mu2>30.0</mu2>
        <maxVel>1.0</maxVel>
        <minDepth>0.001</minDepth>
    </gazebo>
    <!-- Link5 -->
    <gazebo reference="link5">
        <selfCollide>true</selfCollide>
        <kp>1000000.0</kp>
        <kd>100.0</kd>
        <mu1>30.0</mu1>
        <mu2>30.0</mu2>
        <maxVel>1.0</maxVel>
        <minDepth>0.001</minDepth>
    </gazebo>
    <!-- Link6 -->
    <gazebo reference="link6">
        <selfCollide>true</selfCollide>
        <kp>1000000.0</kp>
        <kd>100.0</kd>
        <mu1>30.0</mu1>
        <mu2>30.0</mu2>
        <maxVel>1.0</maxVel>
        <minDepth>0.001</minDepth>
    </gazebo>
    <!-- ros_control plugin -->
    <gazebo>
        <selfCollide>true</selfCollide>
        <plugin filename="libgazebo_ros_control.so" name="gazebo_ros_control">
            <robotNamespace>/dsr</robotNamespace>
            <controlPeriod>0.001</controlPeriod>
            <robotSimType>gazebo_ros_control/DefaultRobotHWSim</robotSimType>
            <legacyModeNS>true</legacyModeNS>
        </plugin>
    </gazebo>
    <link name="world" />
    <!-- World fixed joint-->
    <joint name="world_fixed" type="fixed">
        <origin rpy="0 0 0" xyz="0 0 0.05" />
        <parent link="world" />
        <child link="mobile_base" />
        <!-- <child link="base_0"/> -->
    </joint>
    <!--   xxxxxxxxxxxxxxxxxxxxxxxxxxxxxx  Including Mobile Base  xxxxxxxxxxxxxxxxxxxxxxxxxxxxx -->
    <link name="mobile_base">
        <inertial>
            <mass value="3.722" />
            <origin xyz="-1.2e-05 -6e-05 0.050723" rpy="0 0 0" />
            <inertia ixx="0.011" ixy="-7.19e-06" ixz="-1.94e-06" iyy="0.011" iyz="4.9e-06" izz="0.014" />
        </inertial>
        <visual>
            <origin rpy="0 0 0" xyz="0 0 0" />
            <geometry>
                <mesh filename="package://dsr_description/meshes/base_mobile/base_doosan.STL" />
                <!-- scale="0.001 0.001 0.001"/> -->
            </geometry>
            <material name="dr_gray" />
        </visual>
        <collision>
            <origin rpy="0 0 0" xyz="0 0 0" />
            <geometry>
                <mesh filename="package://dsr_description/meshes/base_mobile/base_doosan.STL" />
            </geometry>
        </collision>
    </link>
    <!-- <link name="base_world"/> -->
    <joint name="fixed" type="fixed">
        <parent link="mobile_base" />
        <child link="base_0" />
        <origin rpy="0 0 0" xyz="-0.15008 -0.0048392 0.800" />
        <axis xyz="0 0 0" />
    </joint>
</robot>

